Workbook

Sheet TARIFAS Home Delivery
B1: Propuesta generada 23 - 6 - 2025. Las tarifas tienen una vigencia de 2 meses para ser aceptadas.
B3: TARIFARIO DISTRIBUCIÓN
M4: =16826+(49.1-20)*685 -> 36759.5 | N4: =M4*1.19 -> 43743.805
B6: PROPUESTA 2EBOX UM - HOME DELIVERY
B7: Tarifas Servicio EXPRESS - PRIORITY | M7: Definiciones DISTRIBUCIÓN:
B8: ORIGEN: SANTIAGO | C8: Quiebres de kilos | M8: 🔵 Las tarifas son afectas a IVA
B9: DESTINO | C9: 0 - 0.5 | D9: 0.5 - 1.5 | E9: 1.5 - 3 | F9: 3 - 6 | G9: 6 - 10 | H9: 10 - 16 | I9: 16 - 20 | J9: 20 - 50 * | K9: > 50 * | M9: 🔵 Tarifa Same Day solo para Región Metropolitana y quiebres hasta los 25 kg como máximo. En caso de sobrepasar este kilomayor máximo se cobrará un valor agregado sobre la tarifa normal.
B10: COPIAPO | C10: 4526 | D10: 4982 | E10: 5537 | F10: 6259 | G10: 7796 | H10: 9314 | I10: 10566 | J10: 541 | K10: 444 | M10: 🔵 El tarifario considera Origen SANTIAGO y Destino Comuna radio BASE. También aplica para origen y destino en la misma ciudad.
B11: LA SERENA | C11: 4244 | D11: 4672 | E11: 5192 | F11: 5869 | G11: 7201 | H11: 8604 | I11: 9767 | J11: 532 | K11: 436 | M11: 🔵 El tarifario se mantiene para un Origen regiones (Comuna Región) y entrega en SANTIAGO.
B12: OVALLE | C12: 4305 | D12: 4741 | E12: 5267 | F12: 5955 | G12: 7131 | H12: 8616 | I12: 9781 | J12: 533 | K12: 437 | M12: 🔵 Las tarifas con Origen distinto a SANTIAGO (zona radio BASE) y destino distinto a SANTIAGO se ponderan x1,2.
B13: LA CALERA | C13: 3710 | D13: 3925 | E13: 4542 | F13: 5282 | G13: 6529 | H13: 7847 | I13: 8814 | J13: 447 | K13: 376 | M13: 🔵 Tarifas con Destino una Comuna con radio INFLUENCIA tienen el mismo precio que radio BASE
B14: LOS ANDES | C14: 3673 | D14: 3886 | E14: 4496 | F14: 5230 | G14: 6465 | H14: 7769 | I14: 8731 | J14: 445 | K14: 374 | M14: 🔵 Tarifas con Destino una Comuna con radio EXTREMO (o MUY EXTREMO) se pondera x1,5
B15: VINA DEL MAR | C15: 3589 | D15: 3839 | E15: 4357 | F15: 5160 | G15: 6411 | H15: 7245 | I15: 8131 | J15: 410 | K15: 340 | M15: 🔵 Envíos a Comunas BORDER considera un costo fijo de $15000 adicional a la tarifa.
B16: SANTIAGO | C16: 2932 | D16: 3041 | E16: 3237 | F16: 3524 | G16: 4081 | H16: 4439 | I16: 5197 | J16: 300 | K16: 229 | M16: 🔵 El costo del envío está asociado al mayor valor entre el peso físico y peso volumétrico. El peso volumétrico es igual a (largo*ancho*alto)/4.000.
B17: MELIPILLA | C17: 3589 | D17: 3839 | E17: 4357 | F17: 5160 | G17: 6411 | H17: 7245 | I17: 8131 | J17: 410 | K17: 340 | M17: *Los cálculos de las tarifas sobre 20kg's y 50kg's, se calculan como kilo adicional sobre las tarifas del quiebre previo.
B18: RANCAGUA | C18: 3673 | D18: 3886 | E18: 4496 | F18: 5230 | G18: 6465 | H18: 7769 | I18: 8731 | J18: 445 | K18: 374 | M18: Ejemplo: tarifa SCL 35 kg´s = $5197 + (35 - 20)*$300.
B19: CURICO | C19: 3822 | D19: 4089 | E19: 4695 | F19: 5392 | G19: 6756 | H19: 8188 | I19: 9170 | J19: 454 | K19: 386 | M19: Ejemplo: tarifa SCL 140 kg´s = $5197 + (50 - 20)*$300 + (140 - 50)*$229.
B20: TALCA | C20: 3822 | D20: 4089 | E20: 4695 | F20: 5392 | G20: 6756 | H20: 8188 | I20: 9170 | J20: 454 | K20: 386
B21: CHILLAN | C21: 4288 | D21: 4579 | E21: 5092 | F21: 5807 | G21: 7082 | H21: 8385 | I21: 9580 | J21: 547 | K21: 441 | M21: ACLARACIONES COBROS EXTRAS:
B22: CONCEPCION | C22: 4288 | D22: 4579 | E22: 5092 | F22: 5807 | G22: 7082 | H22: 8385 | I22: 9580 | J22: 547 | K22: 441
B23: LOS ANGELES | C23: 4440 | D23: 4743 | E23: 5274 | F23: 6013 | G23: 7319 | H23: 8646 | I23: 9847 | J23: 550 | K23: 448 | M23: D.D.: Devolución de Documentos | S23: $900 + iva por Documento
B24: TEMUCO | C24: 4604 | D24: 4839 | E24: 5391 | F24: 6109 | G24: 7563 | H24: 8917 | I24: 10121 | J24: 552 | K24: 451
B25: VALDIVIA | C25: 4956 | D25: 5291 | E25: 5863 | F25: 6489 | G25: 8253 | H25: 9418 | I25: 10641 | J25: 560 | K25: 466
B26: OSORNO | C26: 4956 | D26: 5291 | E26: 5863 | F26: 6489 | G26: 8253 | H26: 9418 | I26: 10641 | J26: 560 | K26: 466
B27: PUERTO MONTT | C27: 4844 | D27: 5170 | E27: 5729 | F27: 6406 | G27: 8039 | H27: 9226 | I27: 10454 | J27: 562 | K27: 457 | M27: TERCEROS INTENTOS EN SANTIAGO Y REGIONES: Tercer intento de entrega de la carga. | S27: $1.500 + $50 por kilo
B28: CASTRO | C28: 5413 | D28: 6042 | E28: 6748 | F28: 8043 | G28: 9379 | H28: 11204 | I28: 12568 | J28: 577 | K28: 471
B30: Extremos Terrestre - Tarifas Servicio EXPRESS | M30: CUSTODIA DE CARGA STGO. Y REGIONES: Se entiende por custodia a toda solicitud de mantener carga hasta posterior coordinación de entrega. Este cobro comenzará a regir a partir del 6to día de almacenada la carga en Hub. | S30: $3.000 x posición de almacenaje x día
B31: DESTINO | C31: 0 - 0.5 | D31: 0.5 - 1.5 | E31: 1.5 - 3 | F31: 3 - 6 | G31: 6 - 10 | H31: 10 - 16 | I31: 16 - 20 | J31: 20 - 50 * | K31: > 50 *
B32: ARICA | C32: 5549 | D32: 6178 | E32: 6792 | F32: 8213 | G32: 10740 | H32: 14176 | I32: 16826 | J32: 685 | K32: 585
B33: IQUIQUE | C33: 5293 | D33: 5773 | E33: 6348 | F33: 7677 | G33: 10038 | H33: 13249 | I33: 15812 | J33: 673 | K33: 559
B34: CALAMA | C34: 5293 | D34: 5773 | E34: 6348 | F34: 7677 | G34: 10038 | H34: 13249 | I34: 15812 | J34: 673 | K34: 559
B35: ANTOFAGASTA | C35: 5081 | D35: 5432 | E35: 5971 | F35: 7220 | G35: 8990 | H35: 11867 | I35: 14235 | J35: 643 | K35: 530 | M35: CONSIDERACIONES DISTRIBUCIÓN:
B36: COYHAIQUE | C36: 5943 | D36: 6631 | E36: 7509 | F36: 9013 | G36: 11211 | H36: 14921 | I36: 17715 | J36: 737 | K36: 569 | M36: *Tarifas válidas para los movimientos de carga declarado por el cliente. Las tarifas se reajustarán semestralmente acorde a la variación que haya experimentado el Indice de Precios al Consumidor (IPC) sumado a otras variables. Estos reajustes pueden variar respecto a negociaciones futuras.
B37: PUNTA ARENAS | C37: 5943 | D37: 6631 | E37: 7509 | F37: 9013 | G37: 11211 | H37: 14921 | I37: 17715 | J37: 737 | K37: 569
B39: Extremos Aéreos - Tarifas Servicio PRIORITY
B40: DESTINO | C40: 0 - 0.5 | D40: 0.5 - 1.5 | E40: 1.5 - 3 | F40: 3 - 6 | G40: 6 - 10 | H40: 10 - 16 | I40: 16 - 20 | J40: 20 - 50 * | K40: > 50 * | M40: ** El cliente tiene un período de 3 meses para alcanzar los movimientos mensuales declarados en la negociación. En caso de incumplimiento, se podría reajustar la tarifa negociada.
B41: ARICA | C41: 6099 | D41: 7189 | E41: 8703 | F41: 10294 | G41: 17165 | H41: 26933 | I41: 31578 | J41: 1559 | K41: 1505
B42: IQUIQUE | C42: 5701 | D42: 6719 | E42: 8135 | F42: 9620 | G42: 16041 | H42: 25174 | I42: 29712 | J42: 1512 | K42: 1422
B43: CALAMA | C43: 5701 | D43: 6719 | E43: 8135 | F43: 9620 | G43: 16041 | H43: 25174 | I43: 29712 | J43: 1512 | K43: 1422 | M43: *** Este Servicio considera un seguro en la tarifa hasta los $85.000 por orden. Sobre ese valor y en caso de querer contar con seguro, se cobra un fee adicional del 0,6% del valor neto de venta del producto.
B44: ANTOFAGASTA | C44: 5517 | D44: 6381 | E44: 7728 | F44: 9139 | G44: 15240 | H44: 23914 | I44: 28296 | J44: 1443 | K44: 1346
...

Sheet COMUNAS - HOME DELIVERY 2026
C2: PROPUESTA 2EBOX UM - HOME DELIVERY
C3: Tarifas Servicio EXPRESS - PRIORITY
C4: ORIGEN: SANTIAGO | F4: 1 | G4: 2 | H4: 3 | I4: 4 | J4: 5 | K4: 6 | L4: 7 | M4: 8 | N4: 9
C5: REGION | D5: POSTA | E5: COMUNA DESTINO | F5: 0 - 0.5 | G5: 0.5 - 1.5 | H5: 1.5 - 3 | I5: 3 - 6 | J5: 6 - 10 | K5: 10 - 16 | L5: 16 - 20 | M5: 20 - 50 * | N5: > 50 *
C6: METROPOLITANA (XIII) | D6: SCL | E6: SANTIAGO | F6: =+'COMUNAS - HOME DELIVERY 2025'!F6*'COMUNAS - HOME DELIVERY 2025'!$Q$7 -> 3025.824 | G6: =+'COMUNAS - HOME DELIVERY 2025'!G6*'COMUNAS - HOME DELIVERY 2025'!$Q$7 -> 3138.312 | H6: =+'COMUNAS - HOME DELIVERY 2025'!H6*'COMUNAS - HOME DELIVERY 2025'!$Q$7 -> 3340.584 | I6: =+'COMUNAS - HOME DELIVERY 2025'!I6*'COMUNAS - HOME DELIVERY 2025'!$Q$7 -> 3636.768 | J6: =+'COMUNAS - HOME DELIVERY 2025'!J6*'COMUNAS - HOME DELIVERY 2025'!$Q$7 -> 4211.592 | K6: =+'COMUNAS - HOME DELIVERY 2025'!K6*'COMUNAS - HOME DELIVERY 2025'!$Q$7 -> 4581.048 | L6: =+'COMUNAS - HOME DELIVERY 2025'!L6*'COMUNAS - HOME DELIVERY 2025'!$Q$7 -> 5363.304 | M6: =+'COMUNAS - HOME DELIVERY 2025'!M6*'COMUNAS - HOME DELIVERY 2025'!$Q$7 -> 309.6 | N6: =+'COMUNAS - HOME DELIVERY 2025'!N6*'COMUNAS - HOME DELIVERY 2025'!$Q$7 -> 236.328
C7: METROPOLITANA (XIII) | D7: RLT | E7: RECOLETA | F7: =+'COMUNAS - HOME DELIVERY 2025'!F7*'COMUNAS - HOME DELIVERY 2025'!$Q$7 -> 3025.824 | G7: =+'COMUNAS - HOME DELIVERY 2025'!G7*'COMUNAS - HOME DELIVERY 2025'!$Q$7 -> 3138.312 | H7: =+'COMUNAS - HOME DELIVERY 2025'!H7*'COMUNAS - HOME DELIVERY 2025'!$Q$7 -> 3340.584 | I7: =+'COMUNAS - HOME DELIVERY 2025'!I7*'COMUNAS - HOME DELIVERY 2025'!$Q$7 -> 3636.768 | J7: =+'COMUNAS - HOME DELIVERY 2025'!J7*'COMUNAS - HOME DELIVERY 2025'!$Q$7 -> 4211.592 | K7: =+'COMUNAS - HOME DELIVERY 2025'!K7*'COMUNAS - HOME DELIVERY 2025'!$Q$7 -> 4581.048 | L7: =+'COMUNAS - HOME DELIVERY 2025'!L7*'COMUNAS - HOME DELIVERY 2025'!$Q$7 -> 5363.304 | M7: =+'COMUNAS - HOME DELIVERY 2025'!M7*'COMUNAS - HOME DELIVERY 2025'!$Q$7 -> 309.6 | N7: =+'COMUNAS - HOME DELIVERY 2025'!N7*'COMUNAS - HOME DELIVERY 2025'!$Q$7 -> 236.328
C8: METROPOLITANA (XIII) | D8: IDP | E8: INDEPENDENCIA | F8: =+'COMUNAS - HOME DELIVERY 2025'!F8*'COMUNAS - HOME DELIVERY 2025'!$Q$7 -> 3025.824 | G8: =+'COMUNAS - HOME DELIVERY 2025'!G8*'COMUNAS - HOME DELIVERY 2025'!$Q$7 -> 3138.312 | H8: =+'COMUNAS - HOME DELIVERY 2025'!H8*'COMUNAS - HOME DELIVERY 2025'!$Q$7 -> 3340.584 | I8: =+'COMUNAS - HOME DELIVERY 2025'!I8*'COMUNAS - HOME DELIVERY 2025'!$Q$7 -> 3636.768 | J8: =+'COMUNAS - HOME DELIVERY 2025'!J8*'COMUNAS - HOME DELIVERY 2025'!$Q$7 -> 4211.592 | K8: =+'COMUNAS - HOME DELIVERY 2025'!K8*'COMUNAS - HOME DELIVERY 2025'!$Q$7 -> 4581.048 | L8: =+'COMUNAS - HOME DELIVERY 2025'!L8*'COMUNAS - HOME DELIVERY 2025'!$Q$7 -> 5363.304 | M8: =+'COMUNAS - HOME DELIVERY 2025'!M8*'COMUNAS - HOME DELIVERY 2025'!$Q$7 -> 309.6 | N8: =+'COMUNAS - HOME DELIVERY 2025'!N8*'COMUNAS - HOME DELIVERY 2025'!$Q$7 -> 236.328
C9: METROPOLITANA (XIII) | D9: QTN | E9: QUINTA NORMAL | F9: =+'COMUNAS - HOME DELIVERY 2025'!F9*'COMUNAS - HOME DELIVERY 2025'!$Q$7 -> 3025.824 | G9: =+'COMUNAS - HOME DELIVERY 2025'!G9*'COMUNAS - HOME DELIVERY 2025'!$Q$7 -> 3138.312 | H9: =+'COMUNAS - HOME DELIVERY 2025'!H9*'COMUNAS - HOME DELIVERY 2025'!$Q$7 -> 3340.584 | I9: =+'COMUNAS - HOME DELIVERY 2025'!I9*'COMUNAS - HOME DELIVERY 2025'!$Q$7 -> 3636.768 | J9: =+'COMUNAS - HOME DELIVERY 2025'!J9*'COMUNAS - HOME DELIVERY 2025'!$Q$7 -> 4211.592 | K9: =+'COMUNAS - HOME DELIVERY 2025'!K9*'COMUNAS - HOME DELIVERY 2025'!$Q$7 -> 4581.048 | L9: =+'COMUNAS - HOME DELIVERY 2025'!L9*'COMUNAS - HOME DELIVERY 2025'!$Q$7 -> 5363.304 | M9: =+'COMUNAS - HOME DELIVERY 2025'!M9*'COMUNAS - HOME DELIVERY 2025'!$Q$7 -> 309.6 | N9: =+'COMUNAS - HOME DELIVERY 2025'!N9*'COMUNAS - HOME DELIVERY 2025'!$Q$7 -> 236.328
C10: METROPOLITANA (XIII) | D10: MAI | E10: MAIPU | F10: =+'COMUNAS - HOME DELIVERY 2025'!F10*'COMUNAS - HOME DELIVERY 2025'!$Q$7 -> 3025.824 | G10: =+'COMUNAS - HOME DELIVERY 2025'!G10*'COMUNAS - HOME DELIVERY 2025'!$Q$7 -> 3138.312 | H10: =+'COMUNAS - HOME DELIVERY 2025'!H10*'COMUNAS - HOME DELIVERY 2025'!$Q$7 -> 3340.584 | I10: =+'COMUNAS - HOME DELIVERY 2025'!I10*'COMUNAS - HOME DELIVERY 2025'!$Q$7 -> 3636.768 | J10: =+'COMUNAS - HOME DELIVERY 2025'!J10*'COMUNAS - HOME DELIVERY 2025'!$Q$7 -> 4211.592 | K10: =+'COMUNAS - HOME DELIVERY 2025'!K10*'COMUNAS - HOME DELIVERY 2025'!$Q$7 -> 4581.048 | L10: =+'COMUNAS - HOME DELIVERY 2025'!L10*'COMUNAS - HOME DELIVERY 2025'!$Q$7 -> 5363.304 | M10: =+'COMUNAS - HOME DELIVERY 2025'!M10*'COMUNAS - HOME DELIVERY 2025'!$Q$7 -> 309.6 | N10: =+'COMUNAS - HOME DELIVERY 2025'!N10*'COMUNAS - HOME DELIVERY 2025'!$Q$7 -> 236.328
C11: METROPOLITANA (XIII) | D11: PUD | E11: PUDAHUEL | F11: =+'COMUNAS - HOME DELIVERY 2025'!F11*'COMUNAS - HOME DELIVERY 2025'!$Q$7 -> 3025.824 | G11: =+'COMUNAS - HOME DELIVERY 2025'!G11*'COMUNAS - HOME DELIVERY 2025'!$Q$7 -> 3138.312 | H11: =+'COMUNAS - HOME DELIVERY 2025'!H11*'COMUNAS - HOME DELIVERY 2025'!$Q$7 -> 3340.584 | I11: =+'COMUNAS - HOME DELIVERY 2025'!I11*'COMUNAS - HOME DELIVERY 2025'!$Q$7 -> 3636.768 | J11: =+'COMUNAS - HOME DELIVERY 2025'!J11*'COMUNAS - HOME DELIVERY 2025'!$Q$7 -> 4211.592 | K11: =+'COMUNAS - HOME DELIVERY 2025'!K11*'COMUNAS - HOME DELIVERY 2025'!$Q$7 -> 4581.048 | L11: =+'COMUNAS - HOME DELIVERY 2025'!L11*'COMUNAS - HOME DELIVERY 2025'!$Q$7 -> 5363.304 | M11: =+'COMUNAS - HOME DELIVERY 2025'!M11*'COMUNAS - HOME DELIVERY 2025'!$Q$7 -> 309.6 | N11: =+'COMUNAS - HOME DELIVERY 2025'!N11*'COMUNAS - HOME DELIVERY 2025'!$Q$7 -> 236.328
C12: METROPOLITANA (XIII) | D12: REN | E12: RENCA | F12: =+'COMUNAS - HOME DELIVERY 2025'!F12*'COMUNAS - HOME DELIVERY 2025'!$Q$7 -> 3025.824 | G12: =+'COMUNAS - HOME DELIVERY 2025'!G12*'COMUNAS - HOME DELIVERY 2025'!$Q$7 -> 3138.312 | H12: =+'COMUNAS - HOME DELIVERY 2025'!H12*'COMUNAS - HOME DELIVERY 2025'!$Q$7 -> 3340.584 | I12: =+'COMUNAS - HOME DELIVERY 2025'!I12*'COMUNAS - HOME DELIVERY 2025'!$Q$7 -> 3636.768 | J12: =+'COMUNAS - HOME DELIVERY 2025'!J12*'COMUNAS - HOME DELIVERY 2025'!$Q$7 -> 4211.592 | K12: =+'COMUNAS - HOME DELIVERY 2025'!K12*'COMUNAS - HOME DELIVERY 2025'!$Q$7 -> 4581.048 | L12: =+'COMUNAS - HOME DELIVERY 2025'!L12*'COMUNAS - HOME DELIVERY 2025'!$Q$7 -> 5363.304 | M12: =+'COMUNAS - HOME DELIVERY 2025'!M12*'COMUNAS - HOME DELIVERY 2025'!$Q$7 -> 309.6 | N12: =+'COMUNAS - HOME DELIVERY 2025'!N12*'COMUNAS - HOME DELIVERY 2025'!$Q$7 -> 236.328
C13: METROPOLITANA (XIII) | D13: QLC | E13: QUILICURA | F13: =+'COMUNAS - HOME DELIVERY 2025'!F13*'COMUNAS - HOME DELIVERY 2025'!$Q$7 -> 3025.824 | G13: =+'COMUNAS - HOME DELIVERY 2025'!G13*'COMUNAS - HOME DELIVERY 2025'!$Q$7 -> 3138.312 | H13: =+'COMUNAS - HOME DELIVERY 2025'!H13*'COMUNAS - HOME DELIVERY 2025'!$Q$7 -> 3340.584 | I13: =+'COMUNAS - HOME DELIVERY 2025'!I13*'COMUNAS - HOME DELIVERY 2025'!$Q$7 -> 3636.768 | J13: =+'COMUNAS - HOME DELIVERY 2025'!J13*'COMUNAS - HOME DELIVERY 2025'!$Q$7 -> 4211.592 | K13: =+'COMUNAS - HOME DELIVERY 2025'!K13*'COMUNAS - HOME DELIVERY 2025'!$Q$7 -> 4581.048 | L13: =+'COMUNAS - HOME DELIVERY 2025'!L13*'COMUNAS - HOME DELIVERY 2025'!$Q$7 -> 5363.304 | M13: =+'COMUNAS - HOME DELIVERY 2025'!M13*'COMUNAS - HOME DELIVERY 2025'!$Q$7 -> 309.6 | N13: =+'COMUNAS - HOME DELIVERY 2025'!N13*'COMUNAS - HOME DELIVERY 2025'!$Q$7 -> 236.328
C14: METROPOLITANA (XIII) | D14: CNH | E14: CONCHALI | F14: =+'COMUNAS - HOME DELIVERY 2025'!F14*'COMUNAS - HOME DELIVERY 2025'!$Q$7 -> 3025.824 | G14: =+'COMUNAS - HOME DELIVERY 2025'!G14*'COMUNAS - HOME DELIVERY 2025'!$Q$7 -> 3138.312 | H14: =+'COMUNAS - HOME DELIVERY 2025'!H14*'COMUNAS - HOME DELIVERY 2025'!$Q$7 -> 3340.584 | I14: =+'COMUNAS - HOME DELIVERY 2025'!I14*'COMUNAS - HOME DELIVERY 2025'!$Q$7 -> 3636.768 | J14: =+'COMUNAS - HOME DELIVERY 2025'!J14*'COMUNAS - HOME DELIVERY 2025'!$Q$7 -> 4211.592 | K14: =+'COMUNAS - HOME DELIVERY 2025'!K14*'COMUNAS - HOME DELIVERY 2025'!$Q$7 -> 4581.048 | L14: =+'COMUNAS - HOME DELIVERY 2025'!L14*'COMUNAS - HOME DELIVERY 2025'!$Q$7 -> 5363.304 | M14: =+'COMUNAS - HOME DELIVERY 2025'!M14*'COMUNAS - HOME DELIVERY 2025'!$Q$7 -> 309.6 | N14: =+'COMUNAS - HOME DELIVERY 2025'!N14*'COMUNAS - HOME DELIVERY 2025'!$Q$7 -> 236.328
C15: METROPOLITANA (XIII) | D15: LPR | E15: LO PRADO | F15: =+'COMUNAS - HOME DELIVERY 2025'!F15*'COMUNAS - HOME DELIVERY 2025'!$Q$7 -> 3025.824 | G15: =+'COMUNAS - HOME DELIVERY 2025'!G15*'COMUNAS - HOME DELIVERY 2025'!$Q$7 -> 3138.312 | H15: =+'COMUNAS - HOME DELIVERY 2025'!H15*'COMUNAS - HOME DELIVERY 2025'!$Q$7 -> 3340.584 | I15: =+'COMUNAS - HOME DELIVERY 2025'!I15*'COMUNAS - HOME DELIVERY 2025'!$Q$7 -> 3636.768 | J15: =+'COMUNAS - HOME DELIVERY 2025'!J15*'COMUNAS - HOME DELIVERY 2025'!$Q$7 -> 4211.592 | K15: =+'COMUNAS - HOME DELIVERY 2025'!K15*'COMUNAS - HOME DELIVERY 2025'!$Q$7 -> 4581.048 | L15: =+'COMUNAS - HOME DELIVERY 2025'!L15*'COMUNAS - HOME DELIVERY 2025'!$Q$7 -> 5363.304 | M15: =+'COMUNAS - HOME DELIVERY 2025'!M15*'COMUNAS - HOME DELIVERY 2025'!$Q$7 -> 309.6 | N15: =+'COMUNAS - HOME DELIVERY 2025'!N15*'COMUNAS - HOME DELIVERY 2025'!$Q$7 -> 236.328
C16: METROPOLITANA (XIII) | D16: CNV | E16: CERRO NAVIA | F16: =+'COMUNAS - HOME DELIVERY 2025'!F16*'COMUNAS - HOME DELIVERY 2025'!$Q$7 -> 3025.824 | G16: =+'COMUNAS - HOME DELIVERY 2025'!G16*'COMUNAS - HOME DELIVERY 2025'!$Q$7 -> 3138.312 | H16: =+'COMUNAS - HOME DELIVERY 2025'!H16*'COMUNAS - HOME DELIVERY 2025'!$Q$7 -> 3340.584 | I16: =+'COMUNAS - HOME DELIVERY 2025'!I16*'COMUNAS - HOME DELIVERY 2025'!$Q$7 -> 3636.768 | J16: =+'COMUNAS - HOME DELIVERY 2025'!J16*'COMUNAS - HOME DELIVERY 2025'!$Q$7 -> 4211.592 | K16: =+'COMUNAS - HOME DELIVERY 2025'!K16*'COMUNAS - HOME DELIVERY 2025'!$Q$7 -> 4581.048 | L16: =+'COMUNAS - HOME DELIVERY 2025'!L16*'COMUNAS - HOME DELIVERY 2025'!$Q$7 -> 5363.304 | M16: =+'COMUNAS - HOME DELIVERY 2025'!M16*'COMUNAS - HOME DELIVERY 2025'!$Q$7 -> 309.6 | N16: =+'COMUNAS - HOME DELIVERY 2025'!N16*'COMUNAS - HOME DELIVERY 2025'!$Q$7 -> 236.328
C17: METROPOLITANA (XIII) | D17: ECE | E17: ESTACION CENTRAL | F17: =+'COMUNAS - HOME DELIVERY 2025'!F17*'COMUNAS - HOME DELIVERY 2025'!$Q$7 -> 3025.824 | G17: =+'COMUNAS - HOME DELIVERY 2025'!G17*'COMUNAS - HOME DELIVERY 2025'!$Q$7 -> 3138.312 | H17: =+'COMUNAS - HOME DELIVERY 2025'!H17*'COMUNAS - HOME DELIVERY 2025'!$Q$7 -> 3340.584 | I17: =+'COMUNAS - HOME DELIVERY 2025'!I17*'COMUNAS - HOME DELIVERY 2025'!$Q$7 -> 3636.768 | J17: =+'COMUNAS - HOME DELIVERY 2025'!J17*'COMUNAS - HOME DELIVERY 2025'!$Q$7 -> 4211.592 | K17: =+'COMUNAS - HOME DELIVERY 2025'!K17*'COMUNAS - HOME DELIVERY 2025'!$Q$7 -> 4581.048 | L17: =+'COMUNAS - HOME DELIVERY 2025'!L17*'COMUNAS - HOME DELIVERY 2025'!$Q$7 -> 5363.304 | M17: =+'COMUNAS - HOME DELIVERY 2025'!M17*'COMUNAS - HOME DELIVERY 2025'!$Q$7 -> 309.6 | N17: =+'COMUNAS - HOME DELIVERY 2025'!N17*'COMUNAS - HOME DELIVERY 2025'!$Q$7 -> 236.328
... C310: LOS LAGOS (X) | D310: SPL | E310: SAN PABLO | F310: =+'COMUNAS - HOME DELIVERY 2025'!F310*'COMUNAS - HOME DELIVERY 2025'!$Q$7 -> 5114.592 | G310: =+'COMUNAS - HOME DELIVERY 2025'!G310*'COMUNAS - HOME DELIVERY 2025'!$Q$7 -> 5460.312 | H310: =+'COMUNAS - HOME DELIVERY 2025'!H310*'COMUNAS - HOME DELIVERY 2025'!$Q$7 -> 6050.616 | I310: =+'COMUNAS - HOME DELIVERY 2025'!I310*'COMUNAS - HOME DELIVERY 2025'!$Q$7 -> 6696.648 | J310: =+'COMUNAS - HOME DELIVERY 2025'!J310*'COMUNAS - HOME DELIVERY 2025'!$Q$7 -> 8517.096 | K310: =+'COMUNAS - HOME DELIVERY 2025'!K310*'COMUNAS - HOME DELIVERY 2025'!$Q$7 -> 9719.376 | L310: =+'COMUNAS - HOME DELIVERY 2025'!L310*'COMUNAS - HOME DELIVERY 2025'!$Q$7 -> 10981.512 | M310: =+'COMUNAS - HOME DELIVERY 2025'!M310*'COMUNAS - HOME DELIVERY 2025'!$Q$7 -> 577.92 | N310: =+'COMUNAS - HOME DELIVERY 2025'!N310*'COMUNAS - HOME DELIVERY 2025'!$Q$7 -> 480.912
C311: Extremos Aéreos - Tarifas Servicio PRIORITY
C312: REGION | D312: POSTA | E312: COMUNA DESTINO | F312: 0 - 0.5 | G312: 0.5 - 1.5 | H312: 1.5 - 3 | I312: 3 - 6 | J312: 6 - 10 | K312: 10 - 16 | L312: 16 - 20 | M312: 20 - 50 * | N312: > 50 *
C313: ARICA Y PARINACOTA (XV) | D313: ARI | E313: ARICA | F313: =+'COMUNAS - HOME DELIVERY 2025'!F313*'COMUNAS - HOME DELIVERY 2025'!$Q$7 -> 6294.168 | G313: =+'COMUNAS - HOME DELIVERY 2025'!G313*'COMUNAS - HOME DELIVERY 2025'!$Q$7 -> 7419.048 | H313: =+'COMUNAS - HOME DELIVERY 2025'!H313*'COMUNAS - HOME DELIVERY 2025'!$Q$7 -> 8981.496 | I313: =+'COMUNAS - HOME DELIVERY 2025'!I313*'COMUNAS - HOME DELIVERY 2025'!$Q$7 -> 10623.408 | J313: =+'COMUNAS - HOME DELIVERY 2025'!J313*'COMUNAS - HOME DELIVERY 2025'!$Q$7 -> 17714.28 | K313: =+'COMUNAS - HOME DELIVERY 2025'!K313*'COMUNAS - HOME DELIVERY 2025'!$Q$7 -> 27794.856 | L313: =+'COMUNAS - HOME DELIVERY 2025'!L313*'COMUNAS - HOME DELIVERY 2025'!$Q$7 -> 32588.496 | M313: =+'COMUNAS - HOME DELIVERY 2025'!M313*'COMUNAS - HOME DELIVERY 2025'!$Q$7 -> 1608.888 | N313: =+'COMUNAS - HOME DELIVERY 2025'!N313*'COMUNAS - HOME DELIVERY 2025'!$Q$7 -> 1553.16
C314: ARICA Y PARINACOTA (XV) | D314: CAM | E314: CAMARONES | F314: =+'COMUNAS - HOME DELIVERY 2025'!F314*'COMUNAS - HOME DELIVERY 2025'!$Q$7 -> 24921.252 | G314: =+'COMUNAS - HOME DELIVERY 2025'!G314*'COMUNAS - HOME DELIVERY 2025'!$Q$7 -> 26608.572 | H314: =+'COMUNAS - HOME DELIVERY 2025'!H314*'COMUNAS - HOME DELIVERY 2025'!$Q$7 -> 28952.244 | I314: =+'COMUNAS - HOME DELIVERY 2025'!I314*'COMUNAS - HOME DELIVERY 2025'!$Q$7 -> 31415.112 | J314: =+'COMUNAS - HOME DELIVERY 2025'!J314*'COMUNAS - HOME DELIVERY 2025'!$Q$7 -> 42051.42 | K314: =+'COMUNAS - HOME DELIVERY 2025'!K314*'COMUNAS - HOME DELIVERY 2025'!$Q$7 -> 57172.284 | L314: =+'COMUNAS - HOME DELIVERY 2025'!L314*'COMUNAS - HOME DELIVERY 2025'!$Q$7 -> 64362.744 | M314: =+'COMUNAS - HOME DELIVERY 2025'!M314*'COMUNAS - HOME DELIVERY 2025'!$Q$7 -> 2413.332 | N314: =+'COMUNAS - HOME DELIVERY 2025'!N314*'COMUNAS - HOME DELIVERY 2025'!$Q$7 -> 2329.74
C315: ARICA Y PARINACOTA (XV) | D315: LGR | E315: GENERAL LAGOS | F315: =+'COMUNAS - HOME DELIVERY 2025'!F315*'COMUNAS - HOME DELIVERY 2025'!$Q$7 -> 24921.252 | G315: =+'COMUNAS - HOME DELIVERY 2025'!G315*'COMUNAS - HOME DELIVERY 2025'!$Q$7 -> 26608.572 | H315: =+'COMUNAS - HOME DELIVERY 2025'!H315*'COMUNAS - HOME DELIVERY 2025'!$Q$7 -> 28952.244 | I315: =+'COMUNAS - HOME DELIVERY 2025'!I315*'COMUNAS - HOME DELIVERY 2025'!$Q$7 -> 31415.112 | J315: =+'COMUNAS - HOME DELIVERY 2025'!J315*'COMUNAS - HOME DELIVERY 2025'!$Q$7 -> 42051.42 | K315: =+'COMUNAS - HOME DELIVERY 2025'!K315*'COMUNAS - HOME DELIVERY 2025'!$Q$7 -> 57172.284 | L315: =+'COMUNAS - HOME DELIVERY 2025'!L315*'COMUNAS - HOME DELIVERY 2025'!$Q$7 -> 64362.744 | M315: =+'COMUNAS - HOME DELIVERY 2025'!M315*'COMUNAS - HOME DELIVERY 2025'!$Q$7 -> 2413.332 | N315: =+'COMUNAS - HOME DELIVERY 2025'!N315*'COMUNAS - HOME DELIVERY 2025'!$Q$7 -> 2329.74
C316: ARICA Y PARINACOTA (XV) | D316: PTR | E316: PUTRE | F316: =+'COMUNAS - HOME DELIVERY 2025'!F316*'COMUNAS - HOME DELIVERY 2025'!$Q$7 -> 24921.252 | G316: =+'COMUNAS - HOME DELIVERY 2025'!G316*'COMUNAS - HOME DELIVERY 2025'!$Q$7 -> 26608.572 | H316: =+'COMUNAS - HOME DELIVERY 2025'!H316*'COMUNAS - HOME DELIVERY 2025'!$Q$7 -> 28952.244 | I316: =+'COMUNAS - HOME DELIVERY 2025'!I316*'COMUNAS - HOME DELIVERY 2025'!$Q$7 -> 31415.112 | J316: =+'COMUNAS - HOME DELIVERY 2025'!J316*'COMUNAS - HOME DELIVERY 2025'!$Q$7 -> 42051.42 | K316: =+'COMUNAS - HOME DELIVERY 2025'!K316*'COMUNAS - HOME DELIVERY 2025'!$Q$7 -> 57172.284 | L316: =+'COMUNAS - HOME DELIVERY 2025'!L316*'COMUNAS - HOME DELIVERY 2025'!$Q$7 -> 64362.744 | M316: =+'COMUNAS - HOME DELIVERY 2025'!M316*'COMUNAS - HOME DELIVERY 2025'!$Q$7 -> 2413.332 | N316: =+'COMUNAS - HOME DELIVERY 2025'!N316*'COMUNAS - HOME DELIVERY 2025'!$Q$7 -> 2329.74
C317: TARAPACA (I) | D317: IQQ | E317: IQUIQUE | F317: =+'COMUNAS - HOME DELIVERY 2025'!F317*'COMUNAS - HOME DELIVERY 2025'!$Q$7 -> 5883.432 | G317: =+'COMUNAS - HOME DELIVERY 2025'!G317*'COMUNAS - HOME DELIVERY 2025'!$Q$7 -> 6934.008 | H317: =+'COMUNAS - HOME DELIVERY 2025'!H317*'COMUNAS - HOME DELIVERY 2025'!$Q$7 -> 8395.32 | I317: =+'COMUNAS - HOME DELIVERY 2025'!I317*'COMUNAS - HOME DELIVERY 2025'!$Q$7 -> 9927.84 | J317: =+'COMUNAS - HOME DELIVERY 2025'!J317*'COMUNAS - HOME DELIVERY 2025'!$Q$7 -> 16554.312 | K317: =+'COMUNAS - HOME DELIVERY 2025'!K317*'COMUNAS - HOME DELIVERY 2025'!$Q$7 -> 25979.568 | L317: =+'COMUNAS - HOME DELIVERY 2025'!L317*'COMUNAS - HOME DELIVERY 2025'!$Q$7 -> 30662.784 | M317: =+'COMUNAS - HOME DELIVERY 2025'!M317*'COMUNAS - HOME DELIVERY 2025'!$Q$7 -> 1560.384 | N317: =+'COMUNAS - HOME DELIVERY 2025'!N317*'COMUNAS - HOME DELIVERY 2025'!$Q$7 -> 1467.504
C318: TARAPACA (I) | D318: AHP | E318: ALTO HOSPICIO | F318: =+'COMUNAS - HOME DELIVERY 2025'!F318*'COMUNAS - HOME DELIVERY 2025'!$Q$7 -> 5883.432 | G318: =+'COMUNAS - HOME DELIVERY 2025'!G318*'COMUNAS - HOME DELIVERY 2025'!$Q$7 -> 6934.008 | H318: =+'COMUNAS - HOME DELIVERY 2025'!H318*'COMUNAS - HOME DELIVERY 2025'!$Q$7 -> 8395.32 | I318: =+'COMUNAS - HOME DELIVERY 2025'!I318*'COMUNAS - HOME DELIVERY 2025'!$Q$7 -> 9927.84 | J318: =+'COMUNAS - HOME DELIVERY 2025'!J318*'COMUNAS - HOME DELIVERY 2025'!$Q$7 -> 16554.312 | K318: =+'COMUNAS - HOME DELIVERY 2025'!K318*'COMUNAS - HOME DELIVERY 2025'!$Q$7 -> 25979.568 | L318: =+'COMUNAS - HOME DELIVERY 2025'!L318*'COMUNAS - HOME DELIVERY 2025'!$Q$7 -> 30662.784 | M318: =+'COMUNAS - HOME DELIVERY 2025'!M318*'COMUNAS - HOME DELIVERY 2025'!$Q$7 -> 1560.384 | N318: =+'COMUNAS - HOME DELIVERY 2025'!N318*'COMUNAS - HOME DELIVERY 2025'!$Q$7 -> 1467.504
C319: TARAPACA (I) | D319: CMN | E319: CAMINA | F319: =+'COMUNAS - HOME DELIVERY 2025'!F319*'COMUNAS - HOME DELIVERY 2025'!$Q$7 -> 24305.148 | G319: =+'COMUNAS - HOME DELIVERY 2025'!G319*'COMUNAS - HOME DELIVERY 2025'!$Q$7 -> 25881.012 | H319: =+'COMUNAS - HOME DELIVERY 2025'!H319*'COMUNAS - HOME DELIVERY 2025'!$Q$7 -> 28072.98 | I319: =+'COMUNAS - HOME DELIVERY 2025'!I319*'COMUNAS - HOME DELIVERY 2025'!$Q$7 -> 30371.76 | J319: =+'COMUNAS - HOME DELIVERY 2025'!J319*'COMUNAS - HOME DELIVERY 2025'!$Q$7 -> 40311.468 | K319: =+'COMUNAS - HOME DELIVERY 2025'!K319*'COMUNAS - HOME DELIVERY 2025'!$Q$7 -> 54449.352 | L319: =+'COMUNAS - HOME DELIVERY 2025'!L319*'COMUNAS - HOME DELIVERY 2025'!$Q$7 -> 61474.176 | M319: =+'COMUNAS - HOME DELIVERY 2025'!M319*'COMUNAS - HOME DELIVERY 2025'!$Q$7 -> 2340.576 | N319: =+'COMUNAS - HOME DELIVERY 2025'!N319*'COMUNAS - HOME DELIVERY 2025'!$Q$7 -> 2201.256
C320: TARAPACA (I) | D320: COE | E320: COLCHANE | F320: =+'COMUNAS - HOME DELIVERY 2025'!F320*'COMUNAS - HOME DELIVERY 2025'!$Q$7 -> 24305.148 | G320: =+'COMUNAS - HOME DELIVERY 2025'!G320*'COMUNAS - HOME DELIVERY 2025'!$Q$7 -> 25881.012 | H320: =+'COMUNAS - HOME DELIVERY 2025'!H320*'COMUNAS - HOME DELIVERY 2025'!$Q$7 -> 28072.98 | I320: =+'COMUNAS - HOME DELIVERY 2025'!I320*'COMUNAS - HOME DELIVERY 2025'!$Q$7 -> 30371.76 | J320: =+'COMUNAS - HOME DELIVERY 2025'!J320*'COMUNAS - HOME DELIVERY 2025'!$Q$7 -> 40311.468 | K320: =+'COMUNAS - HOME DELIVERY 2025'!K320*'COMUNAS - HOME DELIVERY 2025'!$Q$7 -> 54449.352 | L320: =+'COMUNAS - HOME DELIVERY 2025'!L320*'COMUNAS - HOME DELIVERY 2025'!$Q$7 -> 61474.176 | M320: =+'COMUNAS - HOME DELIVERY 2025'!M320*'COMUNAS - HOME DELIVERY 2025'!$Q$7 -> 2340.576 | N320: =+'COMUNAS - HOME DELIVERY 2025'!N320*'COMUNAS - HOME DELIVERY 2025'!$Q$7 -> 2201.256
C321: TARAPACA (I) | D321: HRA | E321: HUARA | F321: =+'COMUNAS - HOME DELIVERY 2025'!F321*'COMUNAS - HOME DELIVERY 2025'!$Q$7 -> 8825.148 | G321: =+'COMUNAS - HOME DELIVERY 2025'!G321*'COMUNAS - HOME DELIVERY 2025'!$Q$7 -> 10401.012 | H321: =+'COMUNAS - HOME DELIVERY 2025'!H321*'COMUNAS - HOME DELIVERY 2025'!$Q$7 -> 12592.98 | I321: =+'COMUNAS - HOME DELIVERY 2025'!I321*'COMUNAS - HOME DELIVERY 2025'!$Q$7 -> 14891.76 | J321: =+'COMUNAS - HOME DELIVERY 2025'!J321*'COMUNAS - HOME DELIVERY 2025'!$Q$7 -> 24831.468 | K321: =+'COMUNAS - HOME DELIVERY 2025'!K321*'COMUNAS - HOME DELIVERY 2025'!$Q$7 -> 38969.352 | L321: =+'COMUNAS - HOME DELIVERY 2025'!L321*'COMUNAS - HOME DELIVERY 2025'!$Q$7 -> 45994.176 | M321: =+'COMUNAS - HOME DELIVERY 2025'!M321*'COMUNAS - HOME DELIVERY 2025'!$Q$7 -> 2340.576 | N321: =+'COMUNAS - HOME DELIVERY 2025'!N321*'COMUNAS - HOME DELIVERY 2025'!$Q$7 -> 2201.256
C322: TARAPACA (I) | D322: OPC | E322: PICA | F322: =+'COMUNAS - HOME DELIVERY 2025'!F322*'COMUNAS - HOME DELIVERY 2025'!$Q$7 -> 8825.148 | G322: =+'COMUNAS - HOME DELIVERY 2025'!G322*'COMUNAS - HOME DELIVERY 2025'!$Q$7 -> 10401.012 | H322: =+'COMUNAS - HOME DELIVERY 2025'!H322*'COMUNAS - HOME DELIVERY 2025'!$Q$7 -> 12592.98 | I322: =+'COMUNAS - HOME DELIVERY 2025'!I322*'COMUNAS - HOME DELIVERY 2025'!$Q$7 -> 14891.76 | J322: =+'COMUNAS - HOME DELIVERY 2025'!J322*'COMUNAS - HOME DELIVERY 2025'!$Q$7 -> 24831.468 | K322: =+'COMUNAS - HOME DELIVERY 2025'!K322*'COMUNAS - HOME DELIVERY 2025'!$Q$7 -> 38969.352 | L322: =+'COMUNAS - HOME DELIVERY 2025'!L322*'COMUNAS - HOME DELIVERY 2025'!$Q$7 -> 45994.176 | M322: =+'COMUNAS - HOME DELIVERY 2025'!M322*'COMUNAS - HOME DELIVERY 2025'!$Q$7 -> 2340.576 | N322: =+'COMUNAS - HOME DELIVERY 2025'!N322*'COMUNAS - HOME DELIVERY 2025'!$Q$7 -> 2201.256
C323: TARAPACA (I) | D323: PAM | E323: POZO ALMONTE | F323: =+'COMUNAS - HOME DELIVERY 2025'!F323*'COMUNAS - HOME DELIVERY 2025'!$Q$7 -> 8825.148 | G323: =+'COMUNAS - HOME DELIVERY 2025'!G323*'COMUNAS - HOME DELIVERY 2025'!$Q$7 -> 10401.012 | H323: =+'COMUNAS - HOME DELIVERY 2025'!H323*'COMUNAS - HOME DELIVERY 2025'!$Q$7 -> 12592.98 | I323: =+'COMUNAS - HOME DELIVERY 2025'!I323*'COMUNAS - HOME DELIVERY 2025'!$Q$7 -> 14891.76 | J323: =+'COMUNAS - HOME DELIVERY 2025'!J323*'COMUNAS - HOME DELIVERY 2025'!$Q$7 -> 24831.468 | K323: =+'COMUNAS - HOME DELIVERY 2025'!K323*'COMUNAS - HOME DELIVERY 2025'!$Q$7 -> 38969.352 | L323: =+'COMUNAS - HOME DELIVERY 2025'!L323*'COMUNAS - HOME DELIVERY 2025'!$Q$7 -> 45994.176 | M323: =+'COMUNAS - HOME DELIVERY 2025'!M323*'COMUNAS - HOME DELIVERY 2025'!$Q$7 -> 2340.576 | N323: =+'COMUNAS - HOME DELIVERY 2025'!N323*'COMUNAS - HOME DELIVERY 2025'!$Q$7 -> 2201.256
C324: ANTOFAGASTA (II) | D324: ANF | E324: ANTOFAGASTA | F324: =+'COMUNAS - HOME DELIVERY 2025'!F324*'COMUNAS - HOME DELIVERY 2025'!$Q$7 -> 5693.544 | G324: =+'COMUNAS - HOME DELIVERY 2025'!G324*'COMUNAS - HOME DELIVERY 2025'!$Q$7 -> 6585.192 | H324: =+'COMUNAS - HOME DELIVERY 2025'!H324*'COMUNAS - HOME DELIVERY 2025'!$Q$7 -> 7975.296 | I324: =+'COMUNAS - HOME DELIVERY 2025'!I324*'COMUNAS - HOME DELIVERY 2025'!$Q$7 -> 9431.448 | J324: =+'COMUNAS - HOME DELIVERY 2025'!J324*'COMUNAS - HOME DELIVERY 2025'!$Q$7 -> 15727.68 | K324: =+'COMUNAS - HOME DELIVERY 2025'!K324*'COMUNAS - HOME DELIVERY 2025'!$Q$7 -> 24679.248 | L324: =+'COMUNAS - HOME DELIVERY 2025'!L324*'COMUNAS - HOME DELIVERY 2025'!$Q$7 -> 29201.472 | M324: =+'COMUNAS - HOME DELIVERY 2025'!M324*'COMUNAS - HOME DELIVERY 2025'!$Q$7 -> 1489.176 | N324: =+'COMUNAS - HOME DELIVERY 2025'!N324*'COMUNAS - HOME DELIVERY 2025'!$Q$7 -> 1389.072
... C353: MAGALLANES (XII) | D353: ATC | E353: ANTARTICA | F353: =+'COMUNAS - HOME DELIVERY 2025'!F353*'COMUNAS - HOME DELIVERY 2025'!$Q$7 -> 25076.052 | G353: =+'COMUNAS - HOME DELIVERY 2025'!G353*'COMUNAS - HOME DELIVERY 2025'!$Q$7 -> 26704.548 | H353: =+'COMUNAS - HOME DELIVERY 2025'!H353*'COMUNAS - HOME DELIVERY 2025'!$Q$7 -> 29062.152 | I353: =+'COMUNAS - HOME DELIVERY 2025'!I353*'COMUNAS - HOME DELIVERY 2025'!$Q$7 -> 30932.136 | J353: =+'COMUNAS - HOME DELIVERY 2025'!J353*'COMUNAS - HOME DELIVERY 2025'!$Q$7 -> 41817.672 | K353: =+'COMUNAS - HOME DELIVERY 2025'!K353*'COMUNAS - HOME DELIVERY 2025'!$Q$7 -> 59133.6 | L353: =+'COMUNAS - HOME DELIVERY 2025'!L353*'COMUNAS - HOME DELIVERY 2025'!$Q$7 -> 66887.532 | M353: =+'COMUNAS - HOME DELIVERY 2025'!M353*'COMUNAS - HOME DELIVERY 2025'!$Q$7 -> 2659.464 | N353: =+'COMUNAS - HOME DELIVERY 2025'!N353*'COMUNAS - HOME DELIVERY 2025'!$Q$7 -> 2507.76
C355: Extremos Terrestre - Tarifas Servicio EXPRESS
C356: REGION | D356: POSTA | E356: COMUNA DESTINO | F356: 0 - 0.5 | G356: 0.5 - 1.5 | H356: 1.5 - 3 | I356: 3 - 6 | J356: 6 - 10 | K356: 10 - 16 | L356: 16 - 20 | M356: 20 - 50 * | N356: > 50 *
C357: ARICA Y PARINACOTA (XV) | D357: ARI | E357: ARICA | F357: =+'COMUNAS - HOME DELIVERY 2025'!F357*'COMUNAS - HOME DELIVERY 2025'!$Q$7 -> 5726.568 | G357: =+'COMUNAS - HOME DELIVERY 2025'!G357*'COMUNAS - HOME DELIVERY 2025'!$Q$7 -> 6375.696 | H357: =+'COMUNAS - HOME DELIVERY 2025'!H357*'COMUNAS - HOME DELIVERY 2025'!$Q$7 -> 7009.344 | I357: =+'COMUNAS - HOME DELIVERY 2025'!I357*'COMUNAS - HOME DELIVERY 2025'!$Q$7 -> 8475.816 | J357: =+'COMUNAS - HOME DELIVERY 2025'!J357*'COMUNAS - HOME DELIVERY 2025'!$Q$7 -> 11083.68 | K357: =+'COMUNAS - HOME DELIVERY 2025'!K357*'COMUNAS - HOME DELIVERY 2025'!$Q$7 -> 14629.632 | L357: =+'COMUNAS - HOME DELIVERY 2025'!L357*'COMUNAS - HOME DELIVERY 2025'!$Q$7 -> 17364.432 | M357: =+'COMUNAS - HOME DELIVERY 2025'!M357*'COMUNAS - HOME DELIVERY 2025'!$Q$7 -> 706.92 | N357: =+'COMUNAS - HOME DELIVERY 2025'!N357*'COMUNAS - HOME DELIVERY 2025'!$Q$7 -> 603.72
C358: ARICA Y PARINACOTA (XV) | D358: CAM | E358: CAMARONES | F358: =+'COMUNAS - HOME DELIVERY 2025'!F358*'COMUNAS - HOME DELIVERY 2025'!$Q$7 -> 24069.852 | G358: =+'COMUNAS - HOME DELIVERY 2025'!G358*'COMUNAS - HOME DELIVERY 2025'!$Q$7 -> 25043.544 | H358: =+'COMUNAS - HOME DELIVERY 2025'!H358*'COMUNAS - HOME DELIVERY 2025'!$Q$7 -> 25994.016 | I358: =+'COMUNAS - HOME DELIVERY 2025'!I358*'COMUNAS - HOME DELIVERY 2025'!$Q$7 -> 28193.724 | J358: =+'COMUNAS - HOME DELIVERY 2025'!J358*'COMUNAS - HOME DELIVERY 2025'!$Q$7 -> 32105.52 | K358: =+'COMUNAS - HOME DELIVERY 2025'!K358*'COMUNAS - HOME DELIVERY 2025'!$Q$7 -> 37424.448 | L358: =+'COMUNAS - HOME DELIVERY 2025'!L358*'COMUNAS - HOME DELIVERY 2025'!$Q$7 -> 41526.648 | M358: =+'COMUNAS - HOME DELIVERY 2025'!M358*'COMUNAS - HOME DELIVERY 2025'!$Q$7 -> 1060.38 | N358: =+'COMUNAS - HOME DELIVERY 2025'!N358*'COMUNAS - HOME DELIVERY 2025'!$Q$7 -> 905.58
C359: ARICA Y PARINACOTA (XV) | D359: LGR | E359: GENERAL LAGOS | F359: =+'COMUNAS - HOME DELIVERY 2025'!F359*'COMUNAS - HOME DELIVERY 2025'!$Q$7 -> 24069.852 | G359: =+'COMUNAS - HOME DELIVERY 2025'!G359*'COMUNAS - HOME DELIVERY 2025'!$Q$7 -> 25043.544 | H359: =+'COMUNAS - HOME DELIVERY 2025'!H359*'COMUNAS - HOME DELIVERY 2025'!$Q$7 -> 25994.016 | I359: =+'COMUNAS - HOME DELIVERY 2025'!I359*'COMUNAS - HOME DELIVERY 2025'!$Q$7 -> 28193.724 | J359: =+'COMUNAS - HOME DELIVERY 2025'!J359*'COMUNAS - HOME DELIVERY 2025'!$Q$7 -> 32105.52 | K359: =+'COMUNAS - HOME DELIVERY 2025'!K359*'COMUNAS - HOME DELIVERY 2025'!$Q$7 -> 37424.448 | L359: =+'COMUNAS - HOME DELIVERY 2025'!L359*'COMUNAS - HOME DELIVERY 2025'!$Q$7 -> 41526.648 | M359: =+'COMUNAS - HOME DELIVERY 2025'!M359*'COMUNAS - HOME DELIVERY 2025'!$Q$7 -> 1060.38 | N359: =+'COMUNAS - HOME DELIVERY 2025'!N359*'COMUNAS - HOME DELIVERY 2025'!$Q$7 -> 905.58
C360: ARICA Y PARINACOTA (XV) | D360: PTR | E360: PUTRE | F360: =+'COMUNAS - HOME DELIVERY 2025'!F360*'COMUNAS - HOME DELIVERY 2025'!$Q$7 -> 24069.852 | G360: =+'COMUNAS - HOME DELIVERY 2025'!G360*'COMUNAS - HOME DELIVERY 2025'!$Q$7 -> 25043.544 | H360: =+'COMUNAS - HOME DELIVERY 2025'!H360*'COMUNAS - HOME DELIVERY 2025'!$Q$7 -> 25994.016 | I360: =+'COMUNAS - HOME DELIVERY 2025'!I360*'COMUNAS - HOME DELIVERY 2025'!$Q$7 -> 28193.724 | J360: =+'COMUNAS - HOME DELIVERY 2025'!J360*'COMUNAS - HOME DELIVERY 2025'!$Q$7 -> 32105.52 | K360: =+'COMUNAS - HOME DELIVERY 2025'!K360*'COMUNAS - HOME DELIVERY 2025'!$Q$7 -> 37424.448 | L360: =+'COMUNAS - HOME DELIVERY 2025'!L360*'COMUNAS - HOME DELIVERY 2025'!$Q$7 -> 41526.648 | M360: =+'COMUNAS - HOME DELIVERY 2025'!M360*'COMUNAS - HOME DELIVERY 2025'!$Q$7 -> 1060.38 | N360: =+'COMUNAS - HOME DELIVERY 2025'!N360*'COMUNAS - HOME DELIVERY 2025'!$Q$7 -> 905.58
C361: TARAPACA (I) | D361: IQQ | E361: IQUIQUE | F361: =+'COMUNAS - HOME DELIVERY 2025'!F361*'COMUNAS - HOME DELIVERY 2025'!$Q$7 -> 5462.376 | G361: =+'COMUNAS - HOME DELIVERY 2025'!G361*'COMUNAS - HOME DELIVERY 2025'!$Q$7 -> 5957.736 | H361: =+'COMUNAS - HOME DELIVERY 2025'!H361*'COMUNAS - HOME DELIVERY 2025'!$Q$7 -> 6551.136 | I361: =+'COMUNAS - HOME DELIVERY 2025'!I361*'COMUNAS - HOME DELIVERY 2025'!$Q$7 -> 7922.664 | J361: =+'COMUNAS - HOME DELIVERY 2025'!J361*'COMUNAS - HOME DELIVERY 2025'!$Q$7 -> 10359.216 | K361: =+'COMUNAS - HOME DELIVERY 2025'!K361*'COMUNAS - HOME DELIVERY 2025'!$Q$7 -> 13672.968 | L361: =+'COMUNAS - HOME DELIVERY 2025'!L361*'COMUNAS - HOME DELIVERY 2025'!$Q$7 -> 16317.984 | M361: =+'COMUNAS - HOME DELIVERY 2025'!M361*'COMUNAS - HOME DELIVERY 2025'!$Q$7 -> 694.536 | N361: =+'COMUNAS - HOME DELIVERY 2025'!N361*'COMUNAS - HOME DELIVERY 2025'!$Q$7 -> 576.888
C362: TARAPACA (I) | D362: AHP | E362: ALTO HOSPICIO | F362: =+'COMUNAS - HOME DELIVERY 2025'!F362*'COMUNAS - HOME DELIVERY 2025'!$Q$7 -> 5462.376 | G362: =+'COMUNAS - HOME DELIVERY 2025'!G362*'COMUNAS - HOME DELIVERY 2025'!$Q$7 -> 5957.736 | H362: =+'COMUNAS - HOME DELIVERY 2025'!H362*'COMUNAS - HOME DELIVERY 2025'!$Q$7 -> 6551.136 | I362: =+'COMUNAS - HOME DELIVERY 2025'!I362*'COMUNAS - HOME DELIVERY 2025'!$Q$7 -> 7922.664 | J362: =+'COMUNAS - HOME DELIVERY 2025'!J362*'COMUNAS - HOME DELIVERY 2025'!$Q$7 -> 10359.216 | K362: =+'COMUNAS - HOME DELIVERY 2025'!K362*'COMUNAS - HOME DELIVERY 2025'!$Q$7 -> 13672.968 | L362: =+'COMUNAS - HOME DELIVERY 2025'!L362*'COMUNAS - HOME DELIVERY 2025'!$Q$7 -> 16317.984 | M362: =+'COMUNAS - HOME DELIVERY 2025'!M362*'COMUNAS - HOME DELIVERY 2025'!$Q$7 -> 694.536 | N362: =+'COMUNAS - HOME DELIVERY 2025'!N362*'COMUNAS - HOME DELIVERY 2025'!$Q$7 -> 576.888
...

Sheet COMUNAS - HOME DELIVERY 2026(2)
C2: PROPUESTA 2EBOX UM - HOME DELIVERY
C3: Tarifas Servicio EXPRESS - PRIORITY
C4: ORIGEN: SANTIAGO | F4: 1 | G4: 2 | H4: 3 | I4: 4 | J4: 5 | K4: 6 | L4: 7 | M4: 8 | N4: 9
C5: REGION | D5: POSTA | E5: COMUNA DESTINO | F5: 0 - 0.5 | G5: 0.5 - 1.5 | H5: 1.5 - 3 | I5: 3 - 6 | J5: 6 - 10 | K5: 10 - 16 | L5: 16 - 20 | M5: 20 - 50 * | N5: > 50 *
C6: METROPOLITANA (XIII) | D6: SCL | E6: SANTIAGO | F6: =+'COMUNAS - HOME DELIVERY 2026'!F6*1.1 -> 3328.4064 | G6: =+'COMUNAS - HOME DELIVERY 2026'!G6*1.1 -> 3452.1432 | H6: =+'COMUNAS - HOME DELIVERY 2026'!H6*1.1 -> 3674.6424 | I6: =+'COMUNAS - HOME DELIVERY 2026'!I6*1.1 -> 4000.4448 | J6: =+'COMUNAS - HOME DELIVERY 2026'!J6*1.1 -> 4632.7512 | K6: =+'COMUNAS - HOME DELIVERY 2026'!K6*1.1 -> 5039.1528 | L6: =+'COMUNAS - HOME DELIVERY 2026'!L6*1.1 -> 5899.6344 | M6: =+'COMUNAS - HOME DELIVERY 2026'!M6*1.1 -> 340.56 | N6: =+'COMUNAS - HOME DELIVERY 2026'!N6*1.1 -> 259.9608
C7: METROPOLITANA (XIII) | D7: RLT | E7: RECOLETA | F7: =+'COMUNAS - HOME DELIVERY 2026'!F7*1.1 -> 3328.4064 | G7: =+'COMUNAS - HOME DELIVERY 2026'!G7*1.1 -> 3452.1432 | H7: =+'COMUNAS - HOME DELIVERY 2026'!H7*1.1 -> 3674.6424 | I7: =+'COMUNAS - HOME DELIVERY 2026'!I7*1.1 -> 4000.4448 | J7: =+'COMUNAS - HOME DELIVERY 2026'!J7*1.1 -> 4632.7512 | K7: =+'COMUNAS - HOME DELIVERY 2026'!K7*1.1 -> 5039.1528 | L7: =+'COMUNAS - HOME DELIVERY 2026'!L7*1.1 -> 5899.6344 | M7: =+'COMUNAS - HOME DELIVERY 2026'!M7*1.1 -> 340.56 | N7: =+'COMUNAS - HOME DELIVERY 2026'!N7*1.1 -> 259.9608
C8: METROPOLITANA (XIII) | D8: IDP | E8: INDEPENDENCIA | F8: =+'COMUNAS - HOME DELIVERY 2026'!F8*1.1 -> 3328.4064 | G8: =+'COMUNAS - HOME DELIVERY 2026'!G8*1.1 -> 3452.1432 | H8: =+'COMUNAS - HOME DELIVERY 2026'!H8*1.1 -> 3674.6424 | I8: =+'COMUNAS - HOME DELIVERY 2026'!I8*1.1 -> 4000.4448 | J8: =+'COMUNAS - HOME DELIVERY 2026'!J8*1.1 -> 4632.7512 | K8: =+'COMUNAS - HOME DELIVERY 2026'!K8*1.1 -> 5039.1528 | L8: =+'COMUNAS - HOME DELIVERY 2026'!L8*1.1 -> 5899.6344 | M8: =+'COMUNAS - HOME DELIVERY 2026'!M8*1.1 -> 340.56 | N8: =+'COMUNAS - HOME DELIVERY 2026'!N8*1.1 -> 259.9608
C9: METROPOLITANA (XIII) | D9: QTN | E9: QUINTA NORMAL | F9: =+'COMUNAS - HOME DELIVERY 2026'!F9*1.1 -> 3328.4064 | G9: =+'COMUNAS - HOME DELIVERY 2026'!G9*1.1 -> 3452.1432 | H9: =+'COMUNAS - HOME DELIVERY 2026'!H9*1.1 -> 3674.6424 | I9: =+'COMUNAS - HOME DELIVERY 2026'!I9*1.1 -> 4000.4448 | J9: =+'COMUNAS - HOME DELIVERY 2026'!J9*1.1 -> 4632.7512 | K9: =+'COMUNAS - HOME DELIVERY 2026'!K9*1.1 -> 5039.1528 | L9: =+'COMUNAS - HOME DELIVERY 2026'!L9*1.1 -> 5899.6344 | M9: =+'COMUNAS - HOME DELIVERY 2026'!M9*1.1 -> 340.56 | N9: =+'COMUNAS - HOME DELIVERY 2026'!N9*1.1 -> 259.9608
C10: METROPOLITANA (XIII) | D10: MAI | E10: MAIPU | F10: =+'COMUNAS - HOME DELIVERY 2026'!F10*1.1 -> 3328.4064 | G10: =+'COMUNAS - HOME DELIVERY 2026'!G10*1.1 -> 3452.1432 | H10: =+'COMUNAS - HOME DELIVERY 2026'!H10*1.1 -> 3674.6424 | I10: =+'COMUNAS - HOME DELIVERY 2026'!I10*1.1 -> 4000.4448 | J10: =+'COMUNAS - HOME DELIVERY 2026'!J10*1.1 -> 4632.7512 | K10: =+'COMUNAS - HOME DELIVERY 2026'!K10*1.1 -> 5039.1528 | L10: =+'COMUNAS - HOME DELIVERY 2026'!L10*1.1 -> 5899.6344 | M10: =+'COMUNAS - HOME DELIVERY 2026'!M10*1.1 -> 340.56 | N10: =+'COMUNAS - HOME DELIVERY 2026'!N10*1.1 -> 259.9608
C11: METROPOLITANA (XIII) | D11: PUD | E11: PUDAHUEL | F11: =+'COMUNAS - HOME DELIVERY 2026'!F11*1.1 -> 3328.4064 | G11: =+'COMUNAS - HOME DELIVERY 2026'!G11*1.1 -> 3452.1432 | H11: =+'COMUNAS - HOME DELIVERY 2026'!H11*1.1 -> 3674.6424 | I11: =+'COMUNAS - HOME DELIVERY 2026'!I11*1.1 -> 4000.4448 | J11: =+'COMUNAS - HOME DELIVERY 2026'!J11*1.1 -> 4632.7512 | K11: =+'COMUNAS - HOME DELIVERY 2026'!K11*1.1 -> 5039.1528 | L11: =+'COMUNAS - HOME DELIVERY 2026'!L11*1.1 -> 5899.6344 | M11: =+'COMUNAS - HOME DELIVERY 2026'!M11*1.1 -> 340.56 | N11: =+'COMUNAS - HOME DELIVERY 2026'!N11*1.1 -> 259.9608
C12: METROPOLITANA (XIII) | D12: REN | E12: RENCA | F12: =+'COMUNAS - HOME DELIVERY 2026'!F12*1.1 -> 3328.4064 | G12: =+'COMUNAS - HOME DELIVERY 2026'!G12*1.1 -> 3452.1432 | H12: =+'COMUNAS - HOME DELIVERY 2026'!H12*1.1 -> 3674.6424 | I12: =+'COMUNAS - HOME DELIVERY 2026'!I12*1.1 -> 4000.4448 | J12: =+'COMUNAS - HOME DELIVERY 2026'!J12*1.1 -> 4632.7512 | K12: =+'COMUNAS - HOME DELIVERY 2026'!K12*1.1 -> 5039.1528 | L12: =+'COMUNAS - HOME DELIVERY 2026'!L12*1.1 -> 5899.6344 | M12: =+'COMUNAS - HOME DELIVERY 2026'!M12*1.1 -> 340.56 | N12: =+'COMUNAS - HOME DELIVERY 2026'!N12*1.1 -> 259.9608
C13: METROPOLITANA (XIII) | D13: QLC | E13: QUILICURA | F13: =+'COMUNAS - HOME DELIVERY 2026'!F13*1.1 -> 3328.4064 | G13: =+'COMUNAS - HOME DELIVERY 2026'!G13*1.1 -> 3452.1432 | H13: =+'COMUNAS - HOME DELIVERY 2026'!H13*1.1 -> 3674.6424 | I13: =+'COMUNAS - HOME DELIVERY 2026'!I13*1.1 -> 4000.4448 | J13: =+'COMUNAS - HOME DELIVERY 2026'!J13*1.1 -> 4632.7512 | K13: =+'COMUNAS - HOME DELIVERY 2026'!K13*1.1 -> 5039.1528 | L13: =+'COMUNAS - HOME DELIVERY 2026'!L13*1.1 -> 5899.6344 | M13: =+'COMUNAS - HOME DELIVERY 2026'!M13*1.1 -> 340.56 | N13: =+'COMUNAS - HOME DELIVERY 2026'!N13*1.1 -> 259.9608
C14: METROPOLITANA (XIII) | D14: CNH | E14: CONCHALI | F14: =+'COMUNAS - HOME DELIVERY 2026'!F14*1.1 -> 3328.4064 | G14: =+'COMUNAS - HOME DELIVERY 2026'!G14*1.1 -> 3452.1432 | H14: =+'COMUNAS - HOME DELIVERY 2026'!H14*1.1 -> 3674.6424 | I14: =+'COMUNAS - HOME DELIVERY 2026'!I14*1.1 -> 4000.4448 | J14: =+'COMUNAS - HOME DELIVERY 2026'!J14*1.1 -> 4632.7512 | K14: =+'COMUNAS - HOME DELIVERY 2026'!K14*1.1 -> 5039.1528 | L14: =+'COMUNAS - HOME DELIVERY 2026'!L14*1.1 -> 5899.6344 | M14: =+'COMUNAS - HOME DELIVERY 2026'!M14*1.1 -> 340.56 | N14: =+'COMUNAS - HOME DELIVERY 2026'!N14*1.1 -> 259.9608
C15: METROPOLITANA (XIII) | D15: LPR | E15: LO PRADO | F15: =+'COMUNAS - HOME DELIVERY 2026'!F15*1.1 -> 3328.4064 | G15: =+'COMUNAS - HOME DELIVERY 2026'!G15*1.1 -> 3452.1432 | H15: =+'COMUNAS - HOME DELIVERY 2026'!H15*1.1 -> 3674.6424 | I15: =+'COMUNAS - HOME DELIVERY 2026'!I15*1.1 -> 4000.4448 | J15: =+'COMUNAS - HOME DELIVERY 2026'!J15*1.1 -> 4632.7512 | K15: =+'COMUNAS - HOME DELIVERY 2026'!K15*1.1 -> 5039.1528 | L15: =+'COMUNAS - HOME DELIVERY 2026'!L15*1.1 -> 5899.6344 | M15: =+'COMUNAS - HOME DELIVERY 2026'!M15*1.1 -> 340.56 | N15: =+'COMUNAS - HOME DELIVERY 2026'!N15*1.1 -> 259.9608
C16: METROPOLITANA (XIII) | D16: CNV | E16: CERRO NAVIA | F16: =+'COMUNAS - HOME DELIVERY 2026'!F16*1.1 -> 3328.4064 | G16: =+'COMUNAS - HOME DELIVERY 2026'!G16*1.1 -> 3452.1432 | H16: =+'COMUNAS - HOME DELIVERY 2026'!H16*1.1 -> 3674.6424 | I16: =+'COMUNAS - HOME DELIVERY 2026'!I16*1.1 -> 4000.4448 | J16: =+'COMUNAS - HOME DELIVERY 2026'!J16*1.1 -> 4632.7512 | K16: =+'COMUNAS - HOME DELIVERY 2026'!K16*1.1 -> 5039.1528 | L16: =+'COMUNAS - HOME DELIVERY 2026'!L16*1.1 -> 5899.6344 | M16: =+'COMUNAS - HOME DELIVERY 2026'!M16*1.1 -> 340.56 | N16: =+'COMUNAS - HOME DELIVERY 2026'!N16*1.1 -> 259.9608
C17: METROPOLITANA (XIII) | D17: ECE | E17: ESTACION CENTRAL | F17: =+'COMUNAS - HOME DELIVERY 2026'!F17*1.1 -> 3328.4064 | G17: =+'COMUNAS - HOME DELIVERY 2026'!G17*1.1 -> 3452.1432 | H17: =+'COMUNAS - HOME DELIVERY 2026'!H17*1.1 -> 3674.6424 | I17: =+'COMUNAS - HOME DELIVERY 2026'!I17*1.1 -> 4000.4448 | J17: =+'COMUNAS - HOME DELIVERY 2026'!J17*1.1 -> 4632.7512 | K17: =+'COMUNAS - HOME DELIVERY 2026'!K17*1.1 -> 5039.1528 | L17: =+'COMUNAS - HOME DELIVERY 2026'!L17*1.1 -> 5899.6344 | M17: =+'COMUNAS - HOME DELIVERY 2026'!M17*1.1 -> 340.56 | N17: =+'COMUNAS - HOME DELIVERY 2026'!N17*1.1 -> 259.9608
... C310: LOS LAGOS (X) | D310: SPL | E310: SAN PABLO | F310: =+'COMUNAS - HOME DELIVERY 2026'!F310*1.1 -> 5626.0512 | G310: =+'COMUNAS - HOME DELIVERY 2026'!G310*1.1 -> 6006.3432 | H310: =+'COMUNAS - HOME DELIVERY 2026'!H310*1.1 -> 6655.6776 | I310: =+'COMUNAS - HOME DELIVERY 2026'!I310*1.1 -> 7366.3128 | J310: =+'COMUNAS - HOME DELIVERY 2026'!J310*1.1 -> 9368.8056 | K310: =+'COMUNAS - HOME DELIVERY 2026'!K310*1.1 -> 10691.314 | L310: =+'COMUNAS - HOME DELIVERY 2026'!L310*1.1 -> 12079.663 | M310: =+'COMUNAS - HOME DELIVERY 2026'!M310*1.1 -> 635.712 | N310: =+'COMUNAS - HOME DELIVERY 2026'!N310*1.1 -> 529.0032
C311: Extremos Aéreos - Tarifas Servicio PRIORITY
C312: REGION | D312: POSTA | E312: COMUNA DESTINO | F312: 0 - 0.5 | G312: 0.5 - 1.5 | H312: 1.5 - 3 | I312: 3 - 6 | J312: 6 - 10 | K312: 10 - 16 | L312: 16 - 20 | M312: 20 - 50 * | N312: > 50 *
C313: ARICA Y PARINACOTA (XV) | D313: ARI | E313: ARICA | F313: =+'COMUNAS - HOME DELIVERY 2026'!F313*1.1 -> 6923.5848 | G313: =+'COMUNAS - HOME DELIVERY 2026'!G313*1.1 -> 8160.9528 | H313: =+'COMUNAS - HOME DELIVERY 2026'!H313*1.1 -> 9879.6456 | I313: =+'COMUNAS - HOME DELIVERY 2026'!I313*1.1 -> 11685.749 | J313: =+'COMUNAS - HOME DELIVERY 2026'!J313*1.1 -> 19485.708 | K313: =+'COMUNAS - HOME DELIVERY 2026'!K313*1.1 -> 30574.342 | L313: =+'COMUNAS - HOME DELIVERY 2026'!L313*1.1 -> 35847.346 | M313: =+'COMUNAS - HOME DELIVERY 2026'!M313*1.1 -> 1769.7768 | N313: =+'COMUNAS - HOME DELIVERY 2026'!N313*1.1 -> 1708.476
C314: ARICA Y PARINACOTA (XV) | D314: CAM | E314: CAMARONES | F314: =+'COMUNAS - HOME DELIVERY 2026'!F314*1.1 -> 27413.377 | G314: =+'COMUNAS - HOME DELIVERY 2026'!G314*1.1 -> 29269.429 | H314: =+'COMUNAS - HOME DELIVERY 2026'!H314*1.1 -> 31847.468 | I314: =+'COMUNAS - HOME DELIVERY 2026'!I314*1.1 -> 34556.623 | J314: =+'COMUNAS - HOME DELIVERY 2026'!J314*1.1 -> 46256.562 | K314: =+'COMUNAS - HOME DELIVERY 2026'!K314*1.1 -> 62889.512 | L314: =+'COMUNAS - HOME DELIVERY 2026'!L314*1.1 -> 70799.018 | M314: =+'COMUNAS - HOME DELIVERY 2026'!M314*1.1 -> 2654.6652 | N314: =+'COMUNAS - HOME DELIVERY 2026'!N314*1.1 -> 2562.714
C315: ARICA Y PARINACOTA (XV) | D315: LGR | E315: GENERAL LAGOS | F315: =+'COMUNAS - HOME DELIVERY 2026'!F315*1.1 -> 27413.377 | G315: =+'COMUNAS - HOME DELIVERY 2026'!G315*1.1 -> 29269.429 | H315: =+'COMUNAS - HOME DELIVERY 2026'!H315*1.1 -> 31847.468 | I315: =+'COMUNAS - HOME DELIVERY 2026'!I315*1.1 -> 34556.623 | J315: =+'COMUNAS - HOME DELIVERY 2026'!J315*1.1 -> 46256.562 | K315: =+'COMUNAS - HOME DELIVERY 2026'!K315*1.1 -> 62889.512 | L315: =+'COMUNAS - HOME DELIVERY 2026'!L315*1.1 -> 70799.018 | M315: =+'COMUNAS - HOME DELIVERY 2026'!M315*1.1 -> 2654.6652 | N315: =+'COMUNAS - HOME DELIVERY 2026'!N315*1.1 -> 2562.714
C316: ARICA Y PARINACOTA (XV) | D316: PTR | E316: PUTRE | F316: =+'COMUNAS - HOME DELIVERY 2026'!F316*1.1 -> 27413.377 | G316: =+'COMUNAS - HOME DELIVERY 2026'!G316*1.1 -> 29269.429 | H316: =+'COMUNAS - HOME DELIVERY 2026'!H316*1.1 -> 31847.468 | I316: =+'COMUNAS - HOME DELIVERY 2026'!I316*1.1 -> 34556.623 | J316: =+'COMUNAS - HOME DELIVERY 2026'!J316*1.1 -> 46256.562 | K316: =+'COMUNAS - HOME DELIVERY 2026'!K316*1.1 -> 62889.512 | L316: =+'COMUNAS - HOME DELIVERY 2026'!L316*1.1 -> 70799.018 | M316: =+'COMUNAS - HOME DELIVERY 2026'!M316*1.1 -> 2654.6652 | N316: =+'COMUNAS - HOME DELIVERY 2026'!N316*1.1 -> 2562.714
C317: TARAPACA (I) | D317: IQQ | E317: IQUIQUE | F317: =+'COMUNAS - HOME DELIVERY 2026'!F317*1.1 -> 6471.7752 | G317: =+'COMUNAS - HOME DELIVERY 2026'!G317*1.1 -> 7627.4088 | H317: =+'COMUNAS - HOME DELIVERY 2026'!H317*1.1 -> 9234.852 | I317: =+'COMUNAS - HOME DELIVERY 2026'!I317*1.1 -> 10920.624 | J317: =+'COMUNAS - HOME DELIVERY 2026'!J317*1.1 -> 18209.743 | K317: =+'COMUNAS - HOME DELIVERY 2026'!K317*1.1 -> 28577.525 | L317: =+'COMUNAS - HOME DELIVERY 2026'!L317*1.1 -> 33729.062 | M317: =+'COMUNAS - HOME DELIVERY 2026'!M317*1.1 -> 1716.4224 | N317: =+'COMUNAS - HOME DELIVERY 2026'!N317*1.1 -> 1614.2544
C318: TARAPACA (I) | D318: AHP | E318: ALTO HOSPICIO | F318: =+'COMUNAS - HOME DELIVERY 2026'!F318*1.1 -> 6471.7752 | G318: =+'COMUNAS - HOME DELIVERY 2026'!G318*1.1 -> 7627.4088 | H318: =+'COMUNAS - HOME DELIVERY 2026'!H318*1.1 -> 9234.852 | I318: =+'COMUNAS - HOME DELIVERY 2026'!I318*1.1 -> 10920.624 | J318: =+'COMUNAS - HOME DELIVERY 2026'!J318*1.1 -> 18209.743 | K318: =+'COMUNAS - HOME DELIVERY 2026'!K318*1.1 -> 28577.525 | L318: =+'COMUNAS - HOME DELIVERY 2026'!L318*1.1 -> 33729.062 | M318: =+'COMUNAS - HOME DELIVERY 2026'!M318*1.1 -> 1716.4224 | N318: =+'COMUNAS - HOME DELIVERY 2026'!N318*1.1 -> 1614.2544
C319: TARAPACA (I) | D319: CMN | E319: CAMINA | F319: =+'COMUNAS - HOME DELIVERY 2026'!F319*1.1 -> 26735.663 | G319: =+'COMUNAS - HOME DELIVERY 2026'!G319*1.1 -> 28469.113 | H319: =+'COMUNAS - HOME DELIVERY 2026'!H319*1.1 -> 30880.278 | I319: =+'COMUNAS - HOME DELIVERY 2026'!I319*1.1 -> 33408.936 | J319: =+'COMUNAS - HOME DELIVERY 2026'!J319*1.1 -> 44342.615 | K319: =+'COMUNAS - HOME DELIVERY 2026'!K319*1.1 -> 59894.287 | L319: =+'COMUNAS - HOME DELIVERY 2026'!L319*1.1 -> 67621.594 | M319: =+'COMUNAS - HOME DELIVERY 2026'!M319*1.1 -> 2574.6336 | N319: =+'COMUNAS - HOME DELIVERY 2026'!N319*1.1 -> 2421.3816
C320: TARAPACA (I) | D320: COE | E320: COLCHANE | F320: =+'COMUNAS - HOME DELIVERY 2026'!F320*1.1 -> 26735.663 | G320: =+'COMUNAS - HOME DELIVERY 2026'!G320*1.1 -> 28469.113 | H320: =+'COMUNAS - HOME DELIVERY 2026'!H320*1.1 -> 30880.278 | I320: =+'COMUNAS - HOME DELIVERY 2026'!I320*1.1 -> 33408.936 | J320: =+'COMUNAS - HOME DELIVERY 2026'!J320*1.1 -> 44342.615 | K320: =+'COMUNAS - HOME DELIVERY 2026'!K320*1.1 -> 59894.287 | L320: =+'COMUNAS - HOME DELIVERY 2026'!L320*1.1 -> 67621.594 | M320: =+'COMUNAS - HOME DELIVERY 2026'!M320*1.1 -> 2574.6336 | N320: =+'COMUNAS - HOME DELIVERY 2026'!N320*1.1 -> 2421.3816
C321: TARAPACA (I) | D321: HRA | E321: HUARA | F321: =+'COMUNAS - HOME DELIVERY 2026'!F321*1.1 -> 9707.6628 | G321: =+'COMUNAS - HOME DELIVERY 2026'!G321*1.1 -> 11441.113 | H321: =+'COMUNAS - HOME DELIVERY 2026'!H321*1.1 -> 13852.278 | I321: =+'COMUNAS - HOME DELIVERY 2026'!I321*1.1 -> 16380.936 | J321: =+'COMUNAS - HOME DELIVERY 2026'!J321*1.1 -> 27314.615 | K321: =+'COMUNAS - HOME DELIVERY 2026'!K321*1.1 -> 42866.287 | L321: =+'COMUNAS - HOME DELIVERY 2026'!L321*1.1 -> 50593.594 | M321: =+'COMUNAS - HOME DELIVERY 2026'!M321*1.1 -> 2574.6336 | N321: =+'COMUNAS - HOME DELIVERY 2026'!N321*1.1 -> 2421.3816
C322: TARAPACA (I) | D322: OPC | E322: PICA | F322: =+'COMUNAS - HOME DELIVERY 2026'!F322*1.1 -> 9707.6628 | G322: =+'COMUNAS - HOME DELIVERY 2026'!G322*1.1 -> 11441.113 | H322: =+'COMUNAS - HOME DELIVERY 2026'!H322*1.1 -> 13852.278 | I322: =+'COMUNAS - HOME DELIVERY 2026'!I322*1.1 -> 16380.936 | J322: =+'COMUNAS - HOME DELIVERY 2026'!J322*1.1 -> 27314.615 | K322: =+'COMUNAS - HOME DELIVERY 2026'!K322*1.1 -> 42866.287 | L322: =+'COMUNAS - HOME DELIVERY 2026'!L322*1.1 -> 50593.594 | M322: =+'COMUNAS - HOME DELIVERY 2026'!M322*1.1 -> 2574.6336 | N322: =+'COMUNAS - HOME DELIVERY 2026'!N322*1.1 -> 2421.3816
C323: TARAPACA (I) | D323: PAM | E323: POZO ALMONTE | F323: =+'COMUNAS - HOME DELIVERY 2026'!F323*1.1 -> 9707.6628 | G323: =+'COMUNAS - HOME DELIVERY 2026'!G323*1.1 -> 11441.113 | H323: =+'COMUNAS - HOME DELIVERY 2026'!H323*1.1 -> 13852.278 | I323: =+'COMUNAS - HOME DELIVERY 2026'!I323*1.1 -> 16380.936 | J323: =+'COMUNAS - HOME DELIVERY 2026'!J323*1.1 -> 27314.615 | K323: =+'COMUNAS - HOME DELIVERY 2026'!K323*1.1 -> 42866.287 | L323: =+'COMUNAS - HOME DELIVERY 2026'!L323*1.1 -> 50593.594 | M323: =+'COMUNAS - HOME DELIVERY 2026'!M323*1.1 -> 2574.6336 | N323: =+'COMUNAS - HOME DELIVERY 2026'!N323*1.1 -> 2421.3816
C324: ANTOFAGASTA (II) | D324: ANF | E324: ANTOFAGASTA | F324: =+'COMUNAS - HOME DELIVERY 2026'!F324*1.1 -> 6262.8984 | G324: =+'COMUNAS - HOME DELIVERY 2026'!G324*1.1 -> 7243.7112 | H324: =+'COMUNAS - HOME DELIVERY 2026'!H324*1.1 -> 8772.8256 | I324: =+'COMUNAS - HOME DELIVERY 2026'!I324*1.1 -> 10374.593 | J324: =+'COMUNAS - HOME DELIVERY 2026'!J324*1.1 -> 17300.448 | K324: =+'COMUNAS - HOME DELIVERY 2026'!K324*1.1 -> 27147.173 | L324: =+'COMUNAS - HOME DELIVERY 2026'!L324*1.1 -> 32121.619 | M324: =+'COMUNAS - HOME DELIVERY 2026'!M324*1.1 -> 1638.0936 | N324: =+'COMUNAS - HOME DELIVERY 2026'!N324*1.1 -> 1527.9792
... C353: MAGALLANES (XII) | D353: ATC | E353: ANTARTICA | F353: =+'COMUNAS - HOME DELIVERY 2026'!F353*1.1 -> 27583.657 | G353: =+'COMUNAS - HOME DELIVERY 2026'!G353*1.1 -> 29375.003 | H353: =+'COMUNAS - HOME DELIVERY 2026'!H353*1.1 -> 31968.367 | I353: =+'COMUNAS - HOME DELIVERY 2026'!I353*1.1 -> 34025.35 | J353: =+'COMUNAS - HOME DELIVERY 2026'!J353*1.1 -> 45999.439 | K353: =+'COMUNAS - HOME DELIVERY 2026'!K353*1.1 -> 65046.96 | L353: =+'COMUNAS - HOME DELIVERY 2026'!L353*1.1 -> 73576.285 | M353: =+'COMUNAS - HOME DELIVERY 2026'!M353*1.1 -> 2925.4104 | N353: =+'COMUNAS - HOME DELIVERY 2026'!N353*1.1 -> 2758.536
C355: Extremos Terrestre - Tarifas Servicio EXPRESS
C356: REGION | D356: POSTA | E356: COMUNA DESTINO | F356: 0 - 0.5 | G356: 0.5 - 1.5 | H356: 1.5 - 3 | I356: 3 - 6 | J356: 6 - 10 | K356: 10 - 16 | L356: 16 - 20 | M356: 20 - 50 * | N356: > 50 *
C357: ARICA Y PARINACOTA (XV) | D357: ARI | E357: ARICA | F357: =+'COMUNAS - HOME DELIVERY 2026'!F357*1.1 -> 6299.2248 | G357: =+'COMUNAS - HOME DELIVERY 2026'!G357*1.1 -> 7013.2656 | H357: =+'COMUNAS - HOME DELIVERY 2026'!H357*1.1 -> 7710.2784 | I357: =+'COMUNAS - HOME DELIVERY 2026'!I357*1.1 -> 9323.3976 | J357: =+'COMUNAS - HOME DELIVERY 2026'!J357*1.1 -> 12192.048 | K357: =+'COMUNAS - HOME DELIVERY 2026'!K357*1.1 -> 16092.595 | L357: =+'COMUNAS - HOME DELIVERY 2026'!L357*1.1 -> 19100.875 | M357: =+'COMUNAS - HOME DELIVERY 2026'!M357*1.1 -> 777.612 | N357: =+'COMUNAS - HOME DELIVERY 2026'!N357*1.1 -> 664.092
C358: ARICA Y PARINACOTA (XV) | D358: CAM | E358: CAMARONES | F358: =+'COMUNAS - HOME DELIVERY 2026'!F358*1.1 -> 26476.837 | G358: =+'COMUNAS - HOME DELIVERY 2026'!G358*1.1 -> 27547.898 | H358: =+'COMUNAS - HOME DELIVERY 2026'!H358*1.1 -> 28593.418 | I358: =+'COMUNAS - HOME DELIVERY 2026'!I358*1.1 -> 31013.096 | J358: =+'COMUNAS - HOME DELIVERY 2026'!J358*1.1 -> 35316.072 | K358: =+'COMUNAS - HOME DELIVERY 2026'!K358*1.1 -> 41166.893 | L358: =+'COMUNAS - HOME DELIVERY 2026'!L358*1.1 -> 45679.313 | M358: =+'COMUNAS - HOME DELIVERY 2026'!M358*1.1 -> 1166.418 | N358: =+'COMUNAS - HOME DELIVERY 2026'!N358*1.1 -> 996.138
C359: ARICA Y PARINACOTA (XV) | D359: LGR | E359: GENERAL LAGOS | F359: =+'COMUNAS - HOME DELIVERY 2026'!F359*1.1 -> 26476.837 | G359: =+'COMUNAS - HOME DELIVERY 2026'!G359*1.1 -> 27547.898 | H359: =+'COMUNAS - HOME DELIVERY 2026'!H359*1.1 -> 28593.418 | I359: =+'COMUNAS - HOME DELIVERY 2026'!I359*1.1 -> 31013.096 | J359: =+'COMUNAS - HOME DELIVERY 2026'!J359*1.1 -> 35316.072 | K359: =+'COMUNAS - HOME DELIVERY 2026'!K359*1.1 -> 41166.893 | L359: =+'COMUNAS - HOME DELIVERY 2026'!L359*1.1 -> 45679.313 | M359: =+'COMUNAS - HOME DELIVERY 2026'!M359*1.1 -> 1166.418 | N359: =+'COMUNAS - HOME DELIVERY 2026'!N359*1.1 -> 996.138
C360: ARICA Y PARINACOTA (XV) | D360: PTR | E360: PUTRE | F360: =+'COMUNAS - HOME DELIVERY 2026'!F360*1.1 -> 26476.837 | G360: =+'COMUNAS - HOME DELIVERY 2026'!G360*1.1 -> 27547.898 | H360: =+'COMUNAS - HOME DELIVERY 2026'!H360*1.1 -> 28593.418 | I360: =+'COMUNAS - HOME DELIVERY 2026'!I360*1.1 -> 31013.096 | J360: =+'COMUNAS - HOME DELIVERY 2026'!J360*1.1 -> 35316.072 | K360: =+'COMUNAS - HOME DELIVERY 2026'!K360*1.1 -> 41166.893 | L360: =+'COMUNAS - HOME DELIVERY 2026'!L360*1.1 -> 45679.313 | M360: =+'COMUNAS - HOME DELIVERY 2026'!M360*1.1 -> 1166.418 | N360: =+'COMUNAS - HOME DELIVERY 2026'!N360*1.1 -> 996.138
C361: TARAPACA (I) | D361: IQQ | E361: IQUIQUE | F361: =+'COMUNAS - HOME DELIVERY 2026'!F361*1.1 -> 6008.6136 | G361: =+'COMUNAS - HOME DELIVERY 2026'!G361*1.1 -> 6553.5096 | H361: =+'COMUNAS - HOME DELIVERY 2026'!H361*1.1 -> 7206.2496 | I361: =+'COMUNAS - HOME DELIVERY 2026'!I361*1.1 -> 8714.9304 | J361: =+'COMUNAS - HOME DELIVERY 2026'!J361*1.1 -> 11395.138 | K361: =+'COMUNAS - HOME DELIVERY 2026'!K361*1.1 -> 15040.265 | L361: =+'COMUNAS - HOME DELIVERY 2026'!L361*1.1 -> 17949.782 | M361: =+'COMUNAS - HOME DELIVERY 2026'!M361*1.1 -> 763.9896 | N361: =+'COMUNAS - HOME DELIVERY 2026'!N361*1.1 -> 634.5768
C362: TARAPACA (I) | D362: AHP | E362: ALTO HOSPICIO | F362: =+'COMUNAS - HOME DELIVERY 2026'!F362*1.1 -> 6008.6136 | G362: =+'COMUNAS - HOME DELIVERY 2026'!G362*1.1 -> 6553.5096 | H362: =+'COMUNAS - HOME DELIVERY 2026'!H362*1.1 -> 7206.2496 | I362: =+'COMUNAS - HOME DELIVERY 2026'!I362*1.1 -> 8714.9304 | J362: =+'COMUNAS - HOME DELIVERY 2026'!J362*1.1 -> 11395.138 | K362: =+'COMUNAS - HOME DELIVERY 2026'!K362*1.1 -> 15040.265 | L362: =+'COMUNAS - HOME DELIVERY 2026'!L362*1.1 -> 17949.782 | M362: =+'COMUNAS - HOME DELIVERY 2026'!M362*1.1 -> 763.9896 | N362: =+'COMUNAS - HOME DELIVERY 2026'!N362*1.1 -> 634.5768
...

Sheet CALCULADORA TELONES
B1: **SE TOMA EL VALOR MAYOR ENTRE PESO VOLUMEN Y PESO REAL
B4: Telón 100" + Trípode / Eléctrico
B5: Medidas | C5: Factor | D5: Peso Real | F5: Comuna | G5: Modelo | H5: Envío Neto | I5: Envío Bruto | J5: Envío a Cobrar
B6: =226*19*12 -> 51528 | C6: 4000 | G6: =+B14 -> Telón 60" | H6: =IFERROR(VLOOKUP($F$6,'COMUNAS - HOME DELIVERY 2026(2)'!$E$6:$L$353,5,FALSE),"Por Definir") -> Por Definir | I6: =IFERROR(H6*1.19,"Por Definir") -> Por Definir | J6: =IFERROR(CEILING(I6,1000+1000)-10,"Por Definir") -> Por Definir | K6: (ACTUALMENTE GRATIS)
B7: =B6/C6 -> 12.882 | C7: > | D7: 9 | G7: =+B9 -> Telón 100" | H7: =IFERROR(VLOOKUP($F$6,'COMUNAS - HOME DELIVERY 2026(2)'!$E$6:$L$353,6,FALSE),"Por Definir") -> Por Definir | I7: =IFERROR(H7*1.19,"Por Definir") -> Por Definir | J7: =IFERROR(CEILING(I7,1000+1000)-10,"Por Definir") -> Por Definir
G8: =+B4 -> Telón 100" + Trípode / Eléctrico | H8: =IFERROR(VLOOKUP($F$6,'COMUNAS - HOME DELIVERY 2026(2)'!$E$6:$L$353,7,FALSE),"Por Definir") -> Por Definir | I8: =IFERROR(H8*1.19,"Por Definir") -> Por Definir | J8: =IFERROR(CEILING(I8,1000+1000)-10,"Por Definir") -> Por Definir
B9: Telón 100" | F9: ESCRIBIR COMUNA AQUÍ (MAYÚSCULA SIN TÍLDE)
B10: Medidas | C10: Factor | D10: Peso Real
B11: =226*13*11 -> 32318 | C11: 4000
B12: =B11/C11 -> 8.0795 | C12: = | D12: 8
B14: Telón 60"
B15: Medidas | C15: Factor | D15: Peso Real
B16: =143*13*11 -> 20449 | C16: 4000
B17: =B16/C16 -> 5.11225 | C17: < | D17: 5
B21: Chimenea 40"
B22: Medidas | C22: Factor | D22: Peso Real | F22: Comuna | G22: Modelo | H22: Envío Neto | I22: Envío Bruto | J22: Envío a Cobrar
B23: =110.1*20.5*55 -> 124137.75 | C23: 4000 | G23: =+B21 -> Chimenea 40" | H23: =IFERROR(VLOOKUP($F$23,'COMUNAS - HOME DELIVERY 2026(2)'!$E$6:$N$353,8,FALSE)+((B24-20)*VLOOKUP(F23,'COMUNAS - HOME DELIVERY 2026(2)'!$E$6:$N$353,9,FALSE)),"Por Definir") -> Por Definir | I23: =IFERROR(H23*1.19,"Por Definir") -> Por Definir | J23: =IFERROR(CEILING(I23,1000+1000)-10,"Por Definir") -> Por Definir
B24: =B23/C23 -> 31.034437 | C24: > | D24: 19.5 | G24: =+B26 -> Chimenea 50" | H24: =IFERROR(VLOOKUP($F$23,'COMUNAS - HOME DELIVERY 2026(2)'!$E$6:$N$353,8,FALSE)+((B29-20)*VLOOKUP($F$23,'COMUNAS - HOME DELIVERY 2026(2)'!$E$6:$N$353,9,FALSE)),"Por Definir") -> Por Definir | I24: =IFERROR(H24*1.19,"Por Definir") -> Por Definir | J24: =IFERROR(CEILING(I24,1000+1000)-10,"Por Definir") -> Por Definir
G25: =+B31 -> Chimenea 60" | H25: =IFERROR(VLOOKUP($F$23,'COMUNAS - HOME DELIVERY 2026(2)'!$E$6:$N$353,8,FALSE)+((B34-20)*VLOOKUP($F$23,'COMUNAS - HOME DELIVERY 2026(2)'!$E$6:$N$353,9,FALSE)),"Por Definir") -> Por Definir | I25: =IFERROR(H25*1.19,"Por Definir") -> Por Definir | J25: =IFERROR(CEILING(I25,1000+1000)-10,"Por Definir") -> Por Definir
B26: Chimenea 50" | F26: ESCRIBIR COMUNA AQUÍ (MAYÚSCULA SIN TÍLDE)
B27: Medidas | C27: Factor | D27: Peso Real
B28: =136.8*20.5*55 -> 154242 | C28: 4000
B29: =B28/C28 -> 38.5605 | C29: > | D29: 24.5
B31: Chimenea 60"
B32: Medidas | C32: Factor | D32: Peso Real
B33: =160.9*22.2*55 -> 196458.9 | C33: 4000
B34: =B33/C33 -> 49.114725 | C34: > | D34: 30.5

Sheet CALCULADORA GRAL
B2: Peso (Kg) | D2: ESCRIBIR MAYOR APROXIMADO (EJ: 19,7 KG, ESCRIBIR 20 KG)
B3: Largo (Cm) | D3: ESCRIBIR MAYOR APROXIMADO (EJ: 5,4 CM, ESCRIBIR 5,5)
